Workbook

Sheet Main
A1: ## | B1: Section | C1: Test case description | D1: Test Steps / Test Data | E1: Expected Result | F1: Pass/Fail | G1: Bug id | H1: Created by | I1: QA | J1: Date | K1: Pass/Fail | L1: Bug id | M1: Regression QA | N1: Date | O1: Pass/Fail | P1: Bug id | Q1: Regression QA | R1: Date | S1: Test Estimation (min) | T1: Plus Risks | U1: Total Estimation
B2: Precondition | C2: visit - https://clientbase.pasv.us/v1
A3: MP-001 | B3: Endpoint | C3: Verify endpoint | E3: /v1 | F3: Pass
A4: MP-002 | B4: Logo | C4: Verify logo: exist | E4: as described | F4: Pass
A5: MP-003 | C5: location | E5: left upper corner | F5: Pass
A6: MP-004 | C6: label | E6: "ClientBase" | F6: Pass
A7: MP-005 | C7: clickable | D7: click on the logo | E7: do not trigger any actions on the page | F7: Pass
A8: MP-006 | B8: Login link | C8: Verify link: exist | E8: as described | F8: Pass
A9: MP-007 | C9: location | E9: right upper corner | F9: Pass
A10: MP-008 | C10: label | E10: "Login" | F10: Pass
A11: MP-009 | C11: clickable | D11: click | E11: redirect the user to the login page | F11: Pass
A12: MP-010 | B12: Registration link | C12: Verify link: exist | E12: as described | F12: Pass
A13: MP-011 | C13: location | E13: right upper corner | F13: Pass
A14: MP-012 | C14: label | E14: "Get started — it's free" | F14: Pass
A15: MP-013 | C15: clickable | D15: click | E15: redirect the user to the registration page | F15: Pass
A16: MP-014 | B16: Header | C16: verify: exist | E16: as described | F16: Pass
A17: MP-015 | C17: location | E17: upper center | F17: Pass
A18: MP-016 | C18: label | E18: "Service Accounting for intermediary companies | F18: Pass
A19: MP-017 | B19: Paragrph | C19: verify: exist | E19: as described | F19: Pass
A20: MP-018 | C20: location | E20: under the header | F20: Pass
A21: MP-019 | C21: label | E21: The easiest way to manage the process of receiving and transmitting an order. | F21: Pass
A22: MP-020 | B22: Start now btn | C22: verify: exist | E22: as described | F22: Pass
A23: MP-021 | C23: location | E23: Under the text block | F23: Pass
A24: MP-022 | C24: label | E24: "Start now" | F24: Pass
A25: MP-023 | C25: clickable | D25: click | E25: redirect the user to the registration page | F25: Fail
A26: MP-024 | B26: Logged user view | C26: Verify if logged user can see the nav-bar | D26: 1. Log into the app 2. visit main page | E26: nav-bar should be visable | F26: Pass
F27: -
F28: -
F29: -
F30: -
F31: -
F32: -
F33: -
F34: -
F35: -
F36: -
F37: -
F38: -
... F62: -

Sheet Login
A1: & | B1: Section | C1: Test case description | D1: Test Steps / Test Data | E1: Expected Result | F1: Pass/Fail | G1: Bug id | H1: Created by | I1: QA | J1: Date | K1: Pass/Fail | L1: Bug id | M1: Regression QA | N1: Date | O1: Pass/Fail | P1: Bug id | Q1: Regression QA | R1: Date | S1: Test Estimation (min) | T1: Plus Risks | U1: Total Estimation
B2: Precondition | C2: visit - https://clientbase.pasv.us/v1/user/login
A3: LP-001 | B3: Endpoint | E3: /v1/user/login | F3: Pass
A4: LP-002 | B4: Smoke positive | C4: Verify if user can log into the app with valid credentials | D4: 1. Email: "RegisteredEmail@gmail.com" 2. Password: "ValidPassword" 3. Submit the form | E4: user logged into the app and redirected to clients page | F4: Pass
A5: LP-003 | B5: Smoke negative | C5: Verify if user can't log into the app with invalid credentials | D5: 1. Email: "InvalidEmail@gmail.com" 2. Password: "InvalidPassword" 3. Submit the form | E5: pop-up Authorization failed / user is not logged into the app | F5: Fail | H5: err txt
A6: LP-004 | B6: Logo | C6: Verify logo label, location, & clickability | E6: "ClientBase" / redirect the user to the main page | F6: Pass
A7: LP-005 | B7: Header | C7: Verify label & location | E7: "Welcome back!" | F7: Fail | H7: location
A8: LP-006 | B8: Email field positive | C8: Placeholder | E8: "Email" | F8: Pass
A9: LP-007 | C9: Verify field accept: lowercase latin letter | D9: qwertyuipasdfghjklzxcvbnm@az.com | E9: All chars are visable / no errors | F9: Pass
A10: LP-008 | C10: uppercase latin letters | D10: QWERTYUIOPASDFGHJKLZXCVBNM@az.com | E10: All chars are visable / no errors | F10: Pass
A11: LP-009 | C11: digits | D11: 1234567890@az.com | E11: All chars are visable / no errors | F11: Pass
A12: LP-010 | C12: Special symbols | D12: #-_~!$&'()*+;=:@.@az.com | F12: Fail | H12: ();:
A13: LP-011 | C13: min lenght 6 chars | D13: l@l.az | F13: Pass
A14: LP-012 | C14: max lenght 330 chars | D14: Qwerty1234Qwerty1234Qwerty1234Qwerty1234Qwerty1234Qwerty1234Qwerty1234Qwerty1234Qwerty1234Qwerty1234Qwerty1234Qwerty1234Qwerty1234Qwerty1234Qwerty1234Qwerty1234Qwerty1234Qwerty1234Qwerty1234Qwerty1234Qwerty1234Qwerty1234Qwerty1234Qwerty1234Qwerty1234Qwerty1234Qwerty1234Qwerty1234Qwerty1234Qwerty1234Qwerty1234Qwerty1234Qwerty1234.comcomco | F14: Fail | H14: max=320
A15: LP-013 | C15: local part accept min 1 char | D15: q@qaz.com | E15: All chars are visable / no errors | F15: Pass
A16: LP-014 | C16: local part accept max 64 chars | D16: Do not go over 64 characters before the "@" symbol | E16: All chars are visable / no errors | F16: Pass
A17: LP-015 | C17: Domain part accept min 1 char | D17: q@q.com | E17: All chars are visable / no errors | F17: Pass
A18: LP-016 | C18: Domain part accept max 253 chars | D18: Do not go over 253 characters after the "@" symbol but before the "." symbol | E18: All chars are visable / no errors | F18: Pass
A19: LP-017 | C19: High-domain part accepts min 2 chars | D19: qaz@qwe.co | E19: All chars are visable / no errors | F19: Pass
A20: LP-018 | C20: High-domain part accepts max 11 chars | D20: qa@qwe.comcomcomco | E20: All chars are visable / no errors | F20: Pass
A21: LP-019 | C21: When a user enters valid credentials, green checkmark appear | D21: test@test.com | E21: as per described | F21: Fail
A22: LP-020 | C22: spaces are trimmed | D22: 1. email: " jacksparrow@pirate.com " 2. password: "Pirate666!" 3. submit the form | E22: user logged into the app | F22: n/a
A23: LP-021 | B23: Email field negative | C23: verify if field dosn't accept: non-Latin letters | D23: фуЦАфвавыф@az.com | E23: Error = Email is not valid email | F23: Fail
A24: LP-022 | C24: verify if field doesn't accept symbols other than #-_~!$&'()*+;=:@. | D24: {}[]<>%/\!@qaz.qa | E24: Error = Email is not valid email | F24: Fail | H24: {}
A25: LP-023 | C25: less than 6 char | D25: q@q.q | E25: Error = Must be more than 5 characters | F25: Fail | H25: err txt
A26: LP-024 | C26: more than 330 char | D26: 1. User enters 331 chars 2. Submit the form | E26: Error = Must be less than 331 | F26: Fail | H26: err txt
A27: LP-025 | C27: less than 1 char for local part | D27: user doesn't enter anything before "@" symbol | E27: Error = Email is not valid email | F27: Pass
A28: LP-026 | C28: more than 64 in local part | D28: user enters 65 or more chars before the "@" symbol | E28: Error = Email is not valid email | F28: Fail | H28: 312
A29: LP-027 | C29: less than 1 char in domain part | D29: user doesn't enter anything after "@" and before "." symbol | E29: Error = Email is not valid email | F29: Pass
A30: LP-028 | C30: more than 253 in domain part | D30: user enters 253 or more chars after the "@" and before the "." symbol | E30: Error = Email is not valid email | F30: Fail | H30: 312
A31: LP-029 | C31: less than 2 chars in high domain part | D31: qa@qa.c | E31: Error = Email is not valid email | F31: Pass
A32: LP-030 | C32: more than 11 in top-level domain part | D32: qa@qa.comcomcomcom | E32: Error = Email is not valid email | F32: Fail | H32: 12
A33: LP-031 | C33: emoji | D33: 🥸🥸🥸@qaz.qa | E33: Error = Email is not valid email | F33: Fail
A34: LP-032 | C34: spaces | D34: " " | E34: Error = Email is not valid email | F34: Pass
A35: LP-033 | C35: email without "@" | D35: blabalalsuser.com | E35: Error = Email is not valid email | F35: Pass
A36: LP-034 | C36: email without "." | D36: awdasd3wa@gmailcom | E36: Error = Email is not valid email | F36: Pass
A37: LP-035 | C37: red cross marks appears when user enter invalid email | D37: registerafwawfd.com | E37: as per described | F37: Fail
A38: LP-036 | C38: empty field error | D38: enter data delete data | E38: "Required" error appears under the field | F38: Pass
F39: -
F40: -
...

Sheet Registration
A1: ## | B1: Section | C1: Test case description | D1: Test Steps / Test Data | E1: Expected Result | F1: Pass/Fail | G1: Bug id | H1: Created by | I1: QA | J1: Date | K1: Pass/Fail | L1: Bug id | M1: Regression QA | N1: Date | O1: Pass/Fail | P1: Bug id | Q1: Regression QA | R1: Date | S1: Test Estimation (min) | T1: Plus Risks | U1: Total Estimation
B2: Precondition | C2: visit - https://clientbase.pasv.us/v1/user/register
A3: RP-001 | B3: Endpoint | E3: /v1/user/register | F3: -
A4: RP-002 | B4: Smoke Positive | C4: Verify if user can register into the app with valid credentials | D4: 1. First name: Bob 2. Last name: Marley 3. Email: "UnregisteredEmail@gmail.com" 4. Password: Bob123! 5. Check the box "I have read Terms and agreements" 6. Submit the form | E4: User registered and redirected to the page where it says "We sent you confirmation email to "UnregisteredEmail@gmail.com" | F4: -
A5: RP-003 | B5: Smoke Negative | C5: Verify if user can't register into the app with not unique email | D5: 1. First name: ddd 2. Last name: awdsafd 3. Email "notUniqueEmail@gmail.com" 4. Password: !!!! 5. Check the box "I have read Terms and aagreements" 6. Submit the form | E5: "This e-mail already exist" | F5: -
A6: RP-004 | B6: Logo | C6: Verify logo label and clickability | E6: Top left, redirects user to the main page | F6: -
A7: RP-005 | B7: Header | C7: Verify label and location | E7: "Create an account" | F7: -
A8: RP-006 | B8: First and Last name field positive | C8: Placeholder | E8: "First Name" and "Last Name" | F8: -
A9: RP-007 | C9: Veirfy field accept lowercase Latin letters | D9: qwertyuiopasdfghjklzxcvbnm | E9: all chars are visible no errors | F9: -
A10: RP-008 | C10: Verify field accept uppercase Latin letters | D10: QWERTYUIOPASDFGHJKLZXCVBNM | E10: all chars are visible no errors | F10: -
A11: RP-009 | C11: Verify field accept min 3 chars | D11: lol | E11: all chars are visible no errors | F11: -
A12: RP-010 | C12: Verify field accept max 100 chars | D12: qwertyuioqwertyuiopqwertyuiopqwertyuiopqwertyuiopqwertyuiopqwertyuiopqwertyuiopqwertyuiopqwertyuiop | E12: all chars are visible no errors | F12: -
A13: RP-011 | B13: First and Last name field negative | C13: Verify field doesn't accept non latin letters | D13: ЫАфцаыа | E13: Error: special character are not allowed | F13: -
A14: RP-012 | C14: Verify field doesn't accept numbers | D14: 1234 | E14: Error: User was not created | F14: -
A15: RP-013 | C15: Verify field doesnt accept less than 3 chars | D15: Mo | E15: Error: Must be more than 2 characters | F15: -
A16: RP-014 | C16: Verify field doesn't accept more than 100 chars | D16: qwertyuiopqwertyuiopqwertyuiopqwertyuiopqwertyuiopqwertyuiopqwertyuiopqwertyuiopqwertyuiopqwertyuiopqwertyuiop | E16: Error: User was not created | F16: -
A17: RP-015 | C17: Verify field doesn't accept special chars | D17: (#-_~!$&'()*+;=:@.) | E17: Error: special character are not allowed | F17: -
A18: RP-016 | B18: Email field positive | C18: Placeholder | E18: "Email" | F18: -
A19: RP-017 | C19: Verify field accept: lowercase latin letter | D19: qwertyuipasdfghjklzxcvbnm@az.com | E19: All chars are visable / no errors | F19: -
A20: RP-018 | C20: uppercase latin letters | D20: QWERTYUIOPASDFGHJKLZXCVBNM@az.com | E20: All chars are visable / no errors | F20: -
A21: RP-019 | C21: digits | D21: 1234567890@az.com | E21: All chars are visable / no errors | F21: -
A22: RP-020 | C22: Special symbols | D22: #-_~!$&'()*+;=:@.@az.com | F22: -
A23: RP-021 | C23: min lenght 6 chars | D23: l@l.az | F23: -
A24: RP-022 | C24: max lenght 253 | D24: Qwerty1234Qwerty1234Qwerty1234Qwerty1234Qwerty1234Qwerty1234Qwerty1234Qwerty1234Qwerty1234Qwerty1234Qwerty1234Qwerty1234Qwerty1234Qwerty1234Qwerty1234Qwerty1234Qwerty1234Qwerty1234Qwerty1234Qwerty1234Qwerty1234Qwerty1234Qwerty1234Qwerty1234Qwerty1234Qwerty1234Qwerty1234Qwerty1234Qwerty1234Qwerty1234Qwerty1234Qwerty1234Qwerty1234.comcomco | F24: -
A25: RP-023 | C25: local part accept min 1 char | D25: q@qaz.com | E25: All chars are visable / no errors | F25: -
A26: RP-024 | C26: local part accept max 64 chars | D26: Do not go over 64 characters before the "@" symbol | E26: All chars are visable / no errors | F26: -
A27: RP-025 | C27: Domain part accept min 1 char | D27: q@q.com | E27: All chars are visable / no errors | F27: -
A28: RP-026 | C28: Domain part accept max 253 chars | D28: Do not go over 253 characters after the "@" symbol but before the "." symbol | E28: All chars are visable / no errors | F28: -
A29: RP-027 | C29: High-domain part accepts min 2 chars | D29: qaz@qwe.co | E29: All chars are visable / no errors | F29: -
A30: RP-028 | C30: High-domain part accepts max 11 chars | D30: qa@qwe.comcomcomco | E30: All chars are visable / no errors | F30: -
A31: RP-029 | C31: When a user enters valid credentials, green checkmark appear | D31: test@test.com | E31: as per described | F31: -
A32: RP-030 | C32: spaces are trimmed | D32: 1. email: " jacksparrow@pirate.com " 2. password: "Pirate666!" 3. submit the form | E32: user logged into the app | F32: -
A33: RP-031 | B33: Email field negative | C33: verify if field dosn't accept: non-Latin letters | D33: фуЦАфвавыф@az.com | E33: Error = Email is not valid email | F33: -
A34: RP-032 | C34: verify if field doesn't accept symbols other than #-_~!$&'()*+;=:@. | D34: {}[]<>%/\!@qaz.qa | E34: Error = Email is not valid email | F34: -
A35: RP-033 | C35: less than 6 char | D35: q@q.q | E35: Error = Must be more than 5 characters | F35: -
A36: RP-034 | C36: more than 330 char | D36: 1. User enters 331 chars 2. Submit the form | E36: Error = Must be less than 331 | F36: -
A37: RP-035 | C37: less than 1 char for local part | D37: user doesn't enter anything before "@" symbol | E37: Error = Email is not valid email | F37: -
A38: RP-036 | C38: more than 64 in local part | D38: user enters 65 or more chars before the "@" symbol | E38: Error = Email is not valid email | F38: -
A39: RP-037 | C39: less than 1 char in domain part | D39: user doesn't enter anything after "@" and before "." symbol | E39: Error = Email is not valid email | F39: -
A40: RP-038 | C40: more than 253 in domain part | D40: user enters 253 or more chars after the "@" and before the "." symbol | E40: Error = Email is not valid email | F40: -
...

Sheet ResetPassword
A1: ## | B1: Section | C1: Test case description | D1: Test Steps / Test Data | E1: Expected Result | F1: Pass/Fail | G1: Bug id | H1: Created by | I1: QA | J1: Date | K1: Pass/Fail | L1: Bug id | M1: Regression QA | N1: Date | O1: Pass/Fail | P1: Bug id | Q1: Regression QA | R1: Date | S1: Test Estimation (min) | T1: Plus Risks | U1: Total Estimation
F3: -
F4: -
F5: -
F6: -
F7: -
F8: -
F9: -
F10: -
F11: -
F12: -
F13: -
F14: -
... F32: -

Sheet Search
A1: ## | B1: Section | C1: Test case description | D1: Test Steps / Test Data | E1: Expected Result | F1: Pass/Fail | G1: Bug id | H1: Created by | I1: QA | J1: Date | K1: Pass/Fail | L1: Bug id | M1: Regression QA | N1: Date | O1: Pass/Fail | P1: Bug id | Q1: Regression QA | R1: Date | S1: Test Estimation (min) | T1: Plus Risks | U1: Total Estimation
F3: -
F4: -
F5: -
F6: -
F7: -
F8: -
F9: -
F10: -
F11: -
F12: -
F13: -
F14: -
... F32: -

Sheet Clients
A1: ## | B1: Section | C1: Test case description | D1: Test Steps / Test Data | E1: Expected Result | F1: Pass/Fail | G1: Bug id | H1: Created by | I1: QA | J1: Date | K1: Pass/Fail | L1: Bug id | M1: Regression QA | N1: Date | O1: Pass/Fail | P1: Bug id | Q1: Regression QA | R1: Date | S1: Test Estimation (min) | T1: Plus Risks | U1: Total Estimation
B2: Prescription | C2: 1. Go to the https://clientbase.pasv.us/v2/user/login 2. Login with: login: ValidEmail; password: ValidPassword 3. Go to the clients page - https://clientbase.pasv.us/v2/client
A3: CP-001 | B3: Endpoint | C3: verify endpoint | E3: /client | F3: -
A4: CP-002 | B4: Logo | C4: Verify logo | E4: "ClientBase" upper left/ redirect user to main page | F4: -
A5: CP-003 | B5: Navbar | C5: verify "Clients" tab label and clickability | E5: "Clients" / redirect user to clients page | F5: -
A6: CP-004 | C6: verify "Vendors" tab label and clickability | E6: redirect to vendors dashboard | F6: -
A7: CP-005 | C7: verify "Services" tab label and clickability | E7: redirect to services dashboard | F7: -
A8: CP-006 | C8: verify "Orders" tab label and clickability | E8: redirect to orders dashboard | F8: -
A9: CP-007 | B9: Profile | C9: Verify label/ clickability | E9: conform to current user/ oper drow down list | F9: -
A10: CP-008 | B10: DD list | C10: Verify "Profile" label/ clickability | E10: Redirect to user profile | F10: -
A11: CP-009 | C11: Verify "Settings" label/ clickability | E11: Redired to settings page | F11: -
A12: CP-010 | C12: Verify "Logout" label/ clickability | E12: user logged out / redirect to login page | F12: -
A13: CP-011 | B13: Search fields | C13: First field placeholder & validation | E13: "Search by name" | F13: -
A14: CP-012 | C14: Second field placeholder & validation | E14: "Search by phone" | F14: -
A15: CP-013 | B15: Reset btn | C15: Verify btn label / clickability | E15: "Reset" resets search and deletes the values from the fields | F15: -
A16: CP-014 | B16: Create Client btn | C16: Verify btn label / clickability | E16: "Create Client" / opens the drawer with an empty client's form. | F16: -
A17: CP-015 | B17: Table | C17: Verify colunms has correct names | E17: as per design link | F17: -
A18: CP-016 | C18: Verify user able to see list of clients with correct data in each field | E18: as described | F18: -
A19: CP-017 | B19: Smoke positive | F19: -
A20: CP-018 | B20: Scenarios | F20: -
A21: CP-019 | F21: -
A22: CP-020 | F22: -
A23: CP-021 | F23: -
A24: CP-022 | F24: -
A25: CP-023 | F25: -
A26: CP-024 | F26: -
A27: CP-025 | F27: -
A28: CP-026 | F28: -
A29: CP-027 | F29: -
A30: CP-028 | F30: -
A31: CP-029 | F31: -
A32: CP-030 | F32: -
A33: CP-031 | F33: -
F34: -
F35: -
F36: -
F37: -
F38: -
F39: -
F40: -
...

Sheet Vendors
A1: ## | B1: Section | C1: Test case description | D1: Test Steps / Test Data | E1: Expected Result | F1: Pass/Fail | G1: Bug id | H1: Created by | I1: QA | J1: Date | K1: Pass/Fail | L1: Bug id | M1: Regression QA | N1: Date | O1: Pass/Fail | P1: Bug id | Q1: Regression QA | R1: Date | S1: Test Estimation (min) | T1: Plus Risks | U1: Total Estimation
F3: -
F4: -
F5: -
F6: -
F7: -
F8: -
F9: -
F10: -
F11: -
F12: -
F13: -
F14: -
... F42: -

Sheet Services
A1: ## | B1: Section | C1: Test case description | D1: Test Steps / Test Data | E1: Expected Result | F1: Pass/Fail | G1: Bug id | H1: Created by | I1: QA | J1: Date | K1: Pass/Fail | L1: Bug id | M1: Regression QA | N1: Date | O1: Pass/Fail | P1: Bug id | Q1: Regression QA | R1: Date | S1: Test Estimation (min) | T1: Plus Risks | U1: Total Estimation
F3: -
F4: -
F5: -
F6: -
F7: -
F8: -
F9: -
F10: -
F11: -
F12: -
F13: -
F14: -
... F42: -

Sheet Orders
A1: ## | B1: Section | C1: Test case description | D1: Test Steps / Test Data | E1: Expected Result | F1: Pass/Fail | G1: Bug id | H1: Created by | I1: QA | J1: Date | K1: Pass/Fail | L1: Bug id | M1: Regression QA | N1: Date | O1: Pass/Fail | P1: Bug id | Q1: Regression QA | R1: Date | S1: Test Estimation (min) | T1: Plus Risks | U1: Total Estimation
F3: -
F4: -
F5: -
F6: -
F7: -
F8: -
F9: -
F10: -
F11: -
F12: -
F13: -
F14: -
... F42: -

Sheet Summary
A1: Suite | B1: Estimation (min) | C1: Passed | D1: Failed | E1: N/A | F1: To Do | G1: Totals | H1: Passing percentage
A2: Landing | C2: =COUNTIF(Main!F:F,"=Pass") -> 23 | D2: =COUNTIF(Main!F:F,"=Fail") -> 1 | E2: =COUNTIF(Main!F:F,"=n/a") -> 0 | F2: =COUNTIF(Main!F:F,"=-") -> 36 | G2: =SUM(C2:F2) -> 60 | H2: =IF(G2=F2,0,((C2/(G2-E2-F2))*100)) -> 95.833333
A3: Login | C3: =COUNTIF(Login!F:F,"=Pass") -> 21 | D3: =COUNTIF(Login!F:F,"=Fail") -> 14 | E3: =COUNTIF(Login!F:F,"=n/a") -> 1 | F3: =COUNTIF(Login!F:F,"=-") -> 79 | G3: =SUM(C3:F3) -> 115 | H3: =IF(G3=F3,0,((C3/(G3-E3-F3))*100)) -> 60
A4: Registration | C4: =COUNTIF(Registration!F:F,"=Pass") -> 0 | D4: =COUNTIF(Registration!F:F,"=Fail") -> 5 | E4: =COUNTIF(Registration!F:F,"=n/a") -> 0 | F4: =COUNTIF(Registration!F:F,"=-") -> 110 | G4: =SUM(C4:F4) -> 115 | H4: =IF(G4=F4,0,((C4/(G4-E4-F4))*100)) -> 0
A5: Reset password | C5: =COUNTIF(ResetPassword!F:F,"=Pass") -> 0 | D5: =COUNTIF(ResetPassword!F:F,"=Fail") -> 0 | E5: =COUNTIF(ResetPassword!F:F,"=n/a") -> 0 | F5: =COUNTIF(ResetPassword!F:F,"=-") -> 30 | G5: =SUM(C5:F5) -> 30 | H5: =IF(G5=F5,0,((C5/(G5-E5-F5))*100)) -> 0
A6: Search | C6: =COUNTIF(Search!F:F,"=Pass") -> 0 | D6: =COUNTIF(Search!G:G,"=Fail") -> 0 | E6: =COUNTIF(Search!F:F,"=n/a") -> 0 | F6: =COUNTIF(Search!F:F,"=-") -> 30 | G6: =SUM(C6:F6) -> 30 | H6: =IF(G6=F6,0,((C6/(G6-E6-F6))*100)) -> 0
A7: Clients | C7: =COUNTIF(Clients!F:F,"=Pass") -> 0 | D7: =COUNTIF(Clients!F:F,"=Fail") -> 0 | E7: =COUNTIF(Clients!F:F,"=n/a") -> 0 | F7: =COUNTIF(Clients!F:F,"=-") -> 40 | G7: =SUM(C7:F7) -> 40 | H7: =IF(G7=F7,0,((C7/(G7-E7-F7))*100)) -> 0
A8: Vendors | C8: =COUNTIF(Vendors!F:F,"=Pass") -> 0 | D8: =COUNTIF(Vendors!F:F,"=Fail") -> 0 | E8: =COUNTIF(Vendors!F:F,"=n/a") -> 0 | F8: =COUNTIF(Vendors!F:F,"=-") -> 40 | G8: =SUM(C8:F8) -> 40 | H8: =IF(G8=F8,0,((C8/(G8-E8-F8))*100)) -> 0
A9: Services | C9: =COUNTIF(Services!F:F,"=Pass") -> 0 | D9: =COUNTIF(Services!F:F,"=Fail") -> 0 | E9: =COUNTIF(Services!F:F,"=n/a") -> 0 | F9: =COUNTIF(Services!F:F,"=-") -> 40 | G9: =SUM(C9:F9) -> 40 | H9: =IF(G9=F9,0,((C9/(G9-E9-F9))*100)) -> 0
A10: Orders | C10: =COUNTIF(Orders!F:F,"=Pass") -> 0 | D10: =COUNTIF(Orders!F:F,"=Fail") -> 0 | E10: =COUNTIF(Orders!F:F,"=n/a") -> 0 | F10: =COUNTIF(Orders!F:F,"=-") -> 40 | G10: =SUM(C10:F10) -> 40 | H10: =IF(G10=F10,0,((C10/(G10-E10-F10))*100)) -> 0
A20: TOTAL (min) | B20: =SUM(B2:B18) -> 0 | E20: =B20/60 -> 0 | F20: TOTAL (hrs)
A22: PASSED: | B22: =SUM(C2:C10) -> 44
A23: FAILED: | B23: =SUM(D2:D10) -> 20
A24: N/A | B24: =SUM(E2:E10) -> 1
A25: TODO | B25: =SUM(F2:F10) -> 445
A29: Regression
A30: Suite | B30: Estimation (min) | C30: Passed | D30: Failed | E30: N/A | F30: To Do | H30: Testing Progress:
A52: TOTAL (min) | B52: =SUM(B31:B50) -> 0 | E52: =B52/60 -> 0 | F52: TOTAL (hrs)
A54: PASSED: | B54: =SUM(C31:C50) -> 0
A55: FAILED: | B55: =SUM(D31:D50) -> 0
A56: N/A | B56: =SUM(E31:E50) -> 0
A57: TODO | B57: =SUM(F31:F50) -> 0
